#VRML_SIM R2021a utf8
WorldInfo {
  coordinateSystem "NUE"
}
Viewpoint {
  orientation 0.3567630428426983 0.837087682948577 0.4147340621620093 4.389744908985678
  position -20.739607235153674 16.76425343704468 -8.046071887048377
  follow "robot"
  followType "None"
}
TexturedBackground {
}
TexturedBackgroundLight {
}
RectangleArena {
  floorSize 20 20
  wallHeight 1e-12
}
Transform {
  children [
    Transform {
      translation -8 0.01 -10.01
      children [
        Transform {
          children [
            DEF LINE Shape {
              appearance PBRAppearance {
                baseColor 0 1 0
                metalness 0
              }
              geometry Box {
                size 4 0.0001 0.05
              }
            }
          ]
        }
        Transform {
          translation -1.99 0 1.99
          rotation 0 1 0 -1.5707
          children [
            USE LINE
          ]
        }
        Transform {
          translation -0.01 0 4
          children [
            USE LINE
          ]
        }
        Transform {
          translation 2 0 2
          rotation 0 1 0 1.5707
          children [
            USE LINE
          ]
        }
      ]
    }
    Transform {
      translation -4 0.01 -10.01
      children [
        Transform {
          children [
            DEF LINE Shape {
              appearance PBRAppearance {
                baseColor 0.0235294 0.498039 0
                metalness 0
              }
              geometry Box {
                size 4 0.0001 0.05
              }
            }
          ]
        }
        Transform {
          translation -1.99 0 1.99
          rotation 0 1 0 -1.5707
          children [
            USE LINE
          ]
        }
        Transform {
          translation -0.01 0 4
          children [
            USE LINE
          ]
        }
        Transform {
          translation 2 0 2
          rotation 0 1 0 1.5707
          children [
            USE LINE
          ]
        }
      ]
    }
    Transform {
      translation 0 0.01 -10.01
      children [
        Transform {
          children [
            DEF LINE Shape {
              appearance PBRAppearance {
                baseColor 0.0235294 0.498039 0
                metalness 0
              }
              geometry Box {
                size 4 0.0001 0.05
              }
            }
          ]
        }
        Transform {
          translation -1.99 0 1.99
          rotation 0 1 0 -1.5707
          children [
            USE LINE
          ]
        }
        Transform {
          translation -0.01 0 4
          children [
            USE LINE
          ]
        }
        Transform {
          translation 2 0 2
          rotation 0 1 0 1.5707
          children [
            USE LINE
          ]
        }
      ]
    }
    Transform {
      translation 4 0.01 -10.01
      children [
        Transform {
          children [
            DEF LINE Shape {
              appearance PBRAppearance {
                baseColor 0.0235294 0.498039 0
                metalness 0
              }
              geometry Box {
                size 4 0.0001 0.05
              }
            }
          ]
        }
        Transform {
          translation -1.99 0 1.99
          rotation 0 1 0 -1.5707
          children [
            USE LINE
          ]
        }
        Transform {
          translation -0.01 0 4
          children [
            USE LINE
          ]
        }
        Transform {
          translation 2 0 2
          rotation 0 1 0 1.5707
          children [
            USE LINE
          ]
        }
      ]
    }
    Transform {
      translation 8 0.01 -10.01
      children [
        Transform {
          children [
            DEF LINE Shape {
              appearance PBRAppearance {
                baseColor 0.0235294 0.498039 0
                metalness 0
              }
              geometry Box {
                size 4 0.0001 0.05
              }
            }
          ]
        }
        Transform {
          translation -1.99 0 1.99
          rotation 0 1 0 -1.5707
          children [
            USE LINE
          ]
        }
        Transform {
          translation -0.01 0 4
          children [
            USE LINE
          ]
        }
        Transform {
          translation 2 0 2
          rotation 0 1 0 1.5707
          children [
            USE LINE
          ]
        }
      ]
    }
    Transform {
      translation 8 0.01 -6
      children [
        Transform {
          children [
            DEF LINE Shape {
              appearance PBRAppearance {
                baseColor 0.0235294 0.498039 0
                metalness 0
              }
              geometry Box {
                size 4 0.0001 0.05
              }
            }
          ]
        }
        Transform {
          translation -1.99 0 1.99
          rotation 0 1 0 -1.5707
          children [
            USE LINE
          ]
        }
        Transform {
          translation -0.01 0 4
          children [
            USE LINE
          ]
        }
        Transform {
          translation 2 0 2
          rotation 0 1 0 1.5707
          children [
            USE LINE
          ]
        }
      ]
    }
    Transform {
      translation 8 0.01 -2
      children [
        Transform {
          children [
            DEF LINE Shape {
              appearance PBRAppearance {
                baseColor 0.0235294 0.498039 0
                metalness 0
              }
              geometry Box {
                size 4 0.0001 0.05
              }
            }
          ]
        }
        Transform {
          translation -1.99 0 1.99
          rotation 0 1 0 -1.5707
          children [
            USE LINE
          ]
        }
        Transform {
          translation -0.01 0 4
          children [
            USE LINE
          ]
        }
        Transform {
          translation 2 0 2
          rotation 0 1 0 1.5707
          children [
            USE LINE
          ]
        }
      ]
    }
    Transform {
      translation 8 0.01 2
      children [
        Transform {
          children [
            DEF LINE Shape {
              appearance PBRAppearance {
                baseColor 0.0235294 0.498039 0
                metalness 0
              }
              geometry Box {
                size 4 0.0001 0.05
              }
            }
          ]
        }
        Transform {
          translation -1.99 0 1.99
          rotation 0 1 0 -1.5707
          children [
            USE LINE
          ]
        }
        Transform {
          translation -0.01 0 4
          children [
            USE LINE
          ]
        }
        Transform {
          translation 2 0 2
          rotation 0 1 0 1.5707
          children [
            USE LINE
          ]
        }
      ]
    }
    Transform {
      translation 8 0.01 6
      children [
        Transform {
          children [
            DEF LINE Shape {
              appearance PBRAppearance {
                baseColor 0.0235294 0.498039 0
                metalness 0
              }
              geometry Box {
                size 4 0.0001 0.05
              }
            }
          ]
        }
        Transform {
          translation -1.99 0 1.99
          rotation 0 1 0 -1.5707
          children [
            USE LINE
          ]
        }
        Transform {
          translation -0.01 0 4
          children [
            USE LINE
          ]
        }
        Transform {
          translation 2 0 2
          rotation 0 1 0 1.5707
          children [
            USE LINE
          ]
        }
      ]
    }
    Transform {
      translation 4 0.01 6
      children [
        Transform {
          children [
            DEF LINE Shape {
              appearance PBRAppearance {
                baseColor 0.0235294 0.498039 0
                metalness 0
              }
              geometry Box {
                size 4 0.0001 0.05
              }
            }
          ]
        }
        Transform {
          translation -1.99 0 1.99
          rotation 0 1 0 -1.5707
          children [
            USE LINE
          ]
        }
        Transform {
          translation -0.01 0 4
          children [
            USE LINE
          ]
        }
        Transform {
          translation 2 0 2
          rotation 0 1 0 1.5707
          children [
            USE LINE
          ]
        }
      ]
    }
    Transform {
      translation 0 0.01 6
      children [
        Transform {
          children [
            DEF LINE Shape {
              appearance PBRAppearance {
                baseColor 0.0235294 0.498039 0
                metalness 0
              }
              geometry Box {
                size 4 0.0001 0.05
              }
            }
          ]
        }
        Transform {
          translation -1.99 0 1.99
          rotation 0 1 0 -1.5707
          children [
            USE LINE
          ]
        }
        Transform {
          translation -0.01 0 4
          children [
            USE LINE
          ]
        }
        Transform {
          translation 2 0 2
          rotation 0 1 0 1.5707
          children [
            USE LINE
          ]
        }
      ]
    }
    Transform {
      translation -4 0.01 6
      children [
        Transform {
          children [
            DEF LINE Shape {
              appearance PBRAppearance {
                baseColor 0.0235294 0.498039 0
                metalness 0
              }
              geometry Box {
                size 4 0.0001 0.05
              }
            }
          ]
        }
        Transform {
          translation -1.99 0 1.99
          rotation 0 1 0 -1.5707
          children [
            USE LINE
          ]
        }
        Transform {
          translation -0.01 0 4
          children [
            USE LINE
          ]
        }
        Transform {
          translation 2 0 2
          rotation 0 1 0 1.5707
          children [
            USE LINE
          ]
        }
      ]
    }
    Transform {
      translation -8 0.01 6
      children [
        Transform {
          children [
            DEF LINE Shape {
              appearance PBRAppearance {
                baseColor 0.0235294 0.498039 0
                metalness 0
              }
              geometry Box {
                size 4 0.0001 0.05
              }
            }
          ]
        }
        Transform {
          translation -1.99 0 1.99
          rotation 0 1 0 -1.5707
          children [
            USE LINE
          ]
        }
        Transform {
          translation -0.01 0 4
          children [
            USE LINE
          ]
        }
        Transform {
          translation 2 0 2
          rotation 0 1 0 1.5707
          children [
            USE LINE
          ]
        }
      ]
    }
    Transform {
      translation -8 0.01 2
      children [
        Transform {
          children [
            DEF LINE Shape {
              appearance PBRAppearance {
                baseColor 0.0235294 0.498039 0
                metalness 0
              }
              geometry Box {
                size 4 0.0001 0.05
              }
            }
          ]
        }
        Transform {
          translation -1.99 0 1.99
          rotation 0 1 0 -1.5707
          children [
            USE LINE
          ]
        }
        Transform {
          translation -0.01 0 4
          children [
            USE LINE
          ]
        }
        Transform {
          translation 2 0 2
          rotation 0 1 0 1.5707
          children [
            USE LINE
          ]
        }
      ]
    }
    Transform {
      translation -8 0.01 -2
      children [
        Transform {
          children [
            DEF LINE Shape {
              appearance PBRAppearance {
                baseColor 0.0235294 0.498039 0
                metalness 0
              }
              geometry Box {
                size 4 0.0001 0.05
              }
            }
          ]
        }
        Transform {
          translation -1.99 0 1.99
          rotation 0 1 0 -1.5707
          children [
            USE LINE
          ]
        }
        Transform {
          translation -0.01 0 4
          children [
            USE LINE
          ]
        }
        Transform {
          translation 2 0 2
          rotation 0 1 0 1.5707
          children [
            USE LINE
          ]
        }
      ]
    }
    Transform {
      translation -8 0.01 -6
      children [
        Transform {
          children [
            DEF LINE Shape {
              appearance PBRAppearance {
                baseColor 0.0235294 0.498039 0
                metalness 0
              }
              geometry Box {
                size 4 0.0001 0.05
              }
            }
          ]
        }
        Transform {
          translation -1.99 0 1.99
          rotation 0 1 0 -1.5707
          children [
            USE LINE
          ]
        }
        Transform {
          translation -0.01 0 4
          children [
            USE LINE
          ]
        }
        Transform {
          translation 2 0 2
          rotation 0 1 0 1.5707
          children [
            USE LINE
          ]
        }
      ]
    }
    Transform {
      translation -4 0.01 -6
      children [
        Transform {
          children [
            DEF LINE Shape {
              appearance PBRAppearance {
                baseColor 0.0235294 0.498039 0
                metalness 0
              }
              geometry Box {
                size 4 0.0001 0.05
              }
            }
          ]
        }
        Transform {
          translation -1.99 0 1.99
          rotation 0 1 0 -1.5707
          children [
            USE LINE
          ]
        }
        Transform {
          translation -0.01 0 4
          children [
            USE LINE
          ]
        }
        Transform {
          translation 2 0 2
          rotation 0 1 0 1.5707
          children [
            USE LINE
          ]
        }
      ]
    }
    Transform {
      translation 0 0.01 -6
      children [
        Transform {
          children [
            DEF LINE Shape {
              appearance PBRAppearance {
                baseColor 0.0235294 0.498039 0
                metalness 0
              }
              geometry Box {
                size 4 0.0001 0.05
              }
            }
          ]
        }
        Transform {
          translation -1.99 0 1.99
          rotation 0 1 0 -1.5707
          children [
            USE LINE
          ]
        }
        Transform {
          translation -0.01 0 4
          children [
            USE LINE
          ]
        }
        Transform {
          translation 2 0 2
          rotation 0 1 0 1.5707
          children [
            USE LINE
          ]
        }
      ]
    }
    Transform {
      translation 4 0.01 -6
      children [
        Transform {
          children [
            DEF LINE Shape {
              appearance PBRAppearance {
                baseColor 0.0235294 0.498039 0
                metalness 0
              }
              geometry Box {
                size 4 0.0001 0.05
              }
            }
          ]
        }
        Transform {
          translation -1.99 0 1.99
          rotation 0 1 0 -1.5707
          children [
            USE LINE
          ]
        }
        Transform {
          translation -0.01 0 4
          children [
            USE LINE
          ]
        }
        Transform {
          translation 2 0 2
          rotation 0 1 0 1.5707
          children [
            USE LINE
          ]
        }
      ]
    }
    Transform {
      translation 4 0.01 -2
      children [
        Transform {
          children [
            DEF LINE Shape {
              appearance PBRAppearance {
                baseColor 0.0235294 0.498039 0
                metalness 0
              }
              geometry Box {
                size 4 0.0001 0.05
              }
            }
          ]
        }
        Transform {
          translation -1.99 0 1.99
          rotation 0 1 0 -1.5707
          children [
            USE LINE
          ]
        }
        Transform {
          translation -0.01 0 4
          children [
            USE LINE
          ]
        }
        Transform {
          translation 2 0 2
          rotation 0 1 0 1.5707
          children [
            USE LINE
          ]
        }
      ]
    }
    Transform {
      translation 4 0.01 2
      children [
        Transform {
          children [
            DEF LINE Shape {
              appearance PBRAppearance {
                baseColor 0.0235294 0.498039 0
                metalness 0
              }
              geometry Box {
                size 4 0.0001 0.05
              }
            }
          ]
        }
        Transform {
          translation -1.99 0 1.99
          rotation 0 1 0 -1.5707
          children [
            USE LINE
          ]
        }
        Transform {
          translation -0.01 0 4
          children [
            USE LINE
          ]
        }
        Transform {
          translation 2 0 2
          rotation 0 1 0 1.5707
          children [
            USE LINE
          ]
        }
      ]
    }
    Transform {
      translation 0 0.01 2
      children [
        Transform {
          children [
            DEF LINE Shape {
              appearance PBRAppearance {
                baseColor 0.0235294 0.498039 0
                metalness 0
              }
              geometry Box {
                size 4 0.0001 0.05
              }
            }
          ]
        }
        Transform {
          translation -1.99 0 1.99
          rotation 0 1 0 -1.5707
          children [
            USE LINE
          ]
        }
        Transform {
          translation -0.01 0 4
          children [
            USE LINE
          ]
        }
        Transform {
          translation 2 0 2
          rotation 0 1 0 1.5707
          children [
            USE LINE
          ]
        }
      ]
    }
    Transform {
      translation -4 0.01 2
      children [
        Transform {
          children [
            DEF LINE Shape {
              appearance PBRAppearance {
                baseColor 0.0235294 0.498039 0
                metalness 0
              }
              geometry Box {
                size 4 0.0001 0.05
              }
            }
          ]
        }
        Transform {
          translation -1.99 0 1.99
          rotation 0 1 0 -1.5707
          children [
            USE LINE
          ]
        }
        Transform {
          translation -0.01 0 4
          children [
            USE LINE
          ]
        }
        Transform {
          translation 2 0 2
          rotation 0 1 0 1.5707
          children [
            USE LINE
          ]
        }
      ]
    }
    Transform {
      translation -4 0.01 -2
      children [
        Transform {
          children [
            DEF LINE Shape {
              appearance PBRAppearance {
                baseColor 0.0235294 0.498039 0
                metalness 0
              }
              geometry Box {
                size 4 0.0001 0.05
              }
            }
          ]
        }
        Transform {
          translation -1.99 0 1.99
          rotation 0 1 0 -1.5707
          children [
            USE LINE
          ]
        }
        Transform {
          translation -0.01 0 4
          children [
            USE LINE
          ]
        }
        Transform {
          translation 2 0 2
          rotation 0 1 0 1.5707
          children [
            USE LINE
          ]
        }
      ]
    }
    Transform {
      translation 0 0.01 -2
      children [
        Transform {
          children [
            DEF LINE Shape {
              appearance PBRAppearance {
                baseColor 0.0235294 0.498039 0
                metalness 0
              }
              geometry Box {
                size 4 0.0001 0.05
              }
            }
          ]
        }
        Transform {
          translation -1.99 0 1.99
          rotation 0 1 0 -1.5707
          children [
            USE LINE
          ]
        }
        Transform {
          translation -0.01 0 4
          children [
            USE LINE
          ]
        }
        Transform {
          translation 2 0 2
          rotation 0 1 0 1.5707
          children [
            USE LINE
          ]
        }
      ]
    }
  ]
}
WoodenBox {
  translation -9.232779999999947 0.19960760039112174 -8.789119999999947
  rotation -0.7427202375567159 0.05552739904947863 0.6672955542175413 4.03960723911127e-16
  name "wooden box(4)"
  size 0.4 0.4 0.4
  mass 1
}
WoodenBox {
  translation -5.72587 0.199608 -7.28147
  rotation -0.7427202375567159 0.05552739904947863 0.6672955542175413 4.03960723911127e-16
  name "wooden box(5)"
  size 0.4 0.4 0.4
  mass 1
}
WoodenBox {
  translation -5.74732 0.199608 -9.24522
  rotation -0.7427202375567159 0.05552739904947863 0.6672955542175413 4.03960723911127e-16
  name "wooden box(6)"
  size 0.4 0.4 0.4
  mass 1
}
WoodenBox {
  translation -5.73104 0.199608 -6.73076
  rotation -0.7427202375567159 0.05552739904947863 0.6672955542175413 4.03960723911127e-16
  name "wooden box(9)"
  size 0.4 0.4 0.4
  mass 1
}
WoodenBox {
  translation -2.74819 0.199608 -9.25784
  rotation -0.7427202375567159 0.05552739904947863 0.6672955542175413 4.03960723911127e-16
  name "wooden box(11)"
  size 0.4 0.4 0.4
  mass 1
}
WoodenBox {
  translation -2.77514 0.199608 -7.75646
  rotation -0.7427202375567159 0.05552739904947863 0.6672955542175413 4.03960723911127e-16
  name "wooden box(12)"
  size 0.4 0.4 0.4
  mass 1
}
WoodenBox {
  translation -0.255824 0.199608 -7.73656
  rotation -0.7427202375567159 0.05552739904947863 0.6672955542175413 4.03960723911127e-16
  name "wooden box(13)"
  size 0.4 0.4 0.4
  mass 1
}
WoodenBox {
  translation 1.2576 0.199608 -8.4821
  rotation -0.7427202375567159 0.05552739904947863 0.6672955542175413 4.03960723911127e-16
  name "wooden box(14)"
  size 0.4 0.4 0.4
  mass 1
}
WoodenBox {
  translation 2.25766 0.199608 -8.76527
  rotation -0.7427202375567159 0.05552739904947863 0.6672955542175413 4.03960723911127e-16
  name "wooden box(15)"
  size 0.4 0.4 0.4
  mass 1
}
WoodenBox {
  translation 2.25616 0.199608 -8.24424
  rotation -0.7427202375567159 0.05552739904947863 0.6672955542175413 4.03960723911127e-16
  name "wooden box(24)"
  size 0.4 0.4 0.4
  mass 1
}
WoodenBox {
  translation 2.26027 0.199608 -7.75782
  rotation -0.7427202375567159 0.05552739904947863 0.6672955542175413 4.03960723911127e-16
  name "wooden box(25)"
  size 0.4 0.4 0.4
  mass 1
}
WoodenBox {
  translation 4.68541 0.199608 -7.5108
  rotation -0.7427202375567159 0.05552739904947863 0.6672955542175413 4.03960723911127e-16
  name "wooden box(26)"
  size 0.4 0.4 0.4
  mass 1
}
WoodenBox {
  translation 6.27741 0.199608 -7.49675
  rotation -0.7427202375567159 0.05552739904947863 0.6672955542175413 4.03960723911127e-16
  name "wooden box(29)"
  size 0.4 0.4 0.4
  mass 1
}
WoodenBox {
  translation 6.25835 0.199608 -9.24948
  rotation -0.7427202375567159 0.05552739904947863 0.6672955542175413 4.03960723911127e-16
  name "wooden box(30)"
  size 0.4 0.4 0.4
  mass 1
}
WoodenBox {
  translation 7.24949 0.199608 -9.23925
  rotation -0.7427202375567159 0.05552739904947863 0.6672955542175413 4.03960723911127e-16
  name "wooden box(31)"
  size 0.4 0.4 0.4
  mass 1
}
WoodenBox {
  translation 8.48511 0.199608 -2.7571
  rotation -0.7427202375567159 0.05552739904947863 0.6672955542175413 4.03960723911127e-16
  name "wooden box(32)"
  size 0.4 0.4 0.4
  mass 1
}
WoodenBox {
  translation 6.75746 0.199608 -3.26702
  rotation -0.7427202375567159 0.05552739904947863 0.6672955542175413 4.03960723911127e-16
  name "wooden box(45)"
  size 0.4 0.4 0.4
  mass 1
}
WoodenBox {
  translation 6.25649 0.199608 -2.24572
  rotation -0.7427202375567159 0.05552739904947863 0.6672955542175413 4.03960723911127e-16
  name "wooden box(44)"
  size 0.4 0.4 0.4
  mass 1
}
WoodenBox {
  translation 8.97813 0.199608 -4.28427
  rotation -0.7427202375567159 0.05552739904947863 0.6672955542175413 4.03960723911127e-16
  name "wooden box(43)"
  size 0.4 0.4 0.4
  mass 1
}
WoodenBox {
  translation 7.78711 0.199608 -4.24236
  rotation -0.7427202375567159 0.05552739904947863 0.6672955542175413 4.03960723911127e-16
  name "wooden box(42)"
  size 0.4 0.4 0.4
  mass 1
}
WoodenBox {
  translation 6.75007 0.199608 -5.7376
  rotation -0.7427202375567159 0.05552739904947863 0.6672955542175413 4.03960723911127e-16
  name "wooden box(41)"
  size 0.4 0.4 0.4
  mass 1
}
WoodenBox {
  translation 7.27032 0.199608 -5.73794
  rotation -0.7427202375567159 0.05552739904947863 0.6672955542175413 4.03960723911127e-16
  name "wooden box(40)"
  size 0.4 0.4 0.4
  mass 1
}
WoodenBox {
  translation 8.23458 0.199608 -5.75078
  rotation -0.7427202375567159 0.05552739904947863 0.6672955542175413 4.03960723911127e-16
  name "wooden box(39)"
  size 0.4 0.4 0.4
  mass 1
}
WoodenBox {
  translation 8.74862 0.199608 -5.72658
  rotation -0.7427202375567159 0.05552739904947863 0.6672955542175413 4.03960723911127e-16
  name "wooden box(38)"
  size 0.4 0.4 0.4
  mass 1
}
WoodenBox {
  translation 9.23923 0.199608 -5.73524
  rotation -0.7427202375567159 0.05552739904947863 0.6672955542175413 4.03960723911127e-16
  name "wooden box(37)"
  size 0.4 0.4 0.4
  mass 1
}
WoodenBox {
  translation 7.7429 0.199608 -6.74819
  rotation -0.7427202375567159 0.05552739904947863 0.6672955542175413 4.03960723911127e-16
  name "wooden box(36)"
  size 0.4 0.4 0.4
  mass 1
}
WoodenBox {
  translation 9.26115 0.199608 -9.23381
  rotation -0.7427202375567159 0.05552739904947863 0.6672955542175413 4.03960723911127e-16
  name "wooden box(35)"
  size 0.4 0.4 0.4
  mass 1
}
WoodenBox {
  translation 9.25362 0.199608 -6.75147
  rotation -0.7427202375567159 0.05552739904947863 0.6672955542175413 4.03960723911127e-16
  name "wooden box(34)"
  size 0.4 0.4 0.4
  mass 1
}
WoodenBox {
  translation 8.25387 0.199608 -8.22898
  rotation -0.7427202375567159 0.05552739904947863 0.6672955542175413 4.03960723911127e-16
  name "wooden box(33)"
  size 0.4 0.4 0.4
  mass 1
}
WoodenBox {
  translation 2.24951 0.199608 -6.75558
  rotation -0.7427202375567159 0.05552739904947863 0.6672955542175413 4.03960723911127e-16
  name "wooden box(28)"
  size 0.4 0.4 0.4
  mass 1
}
WoodenBox {
  translation 2.25093 0.199608 -7.28327
  rotation -0.7427202375567159 0.05552739904947863 0.6672955542175413 4.03960723911127e-16
  name "wooden box(27)"
  size 0.4 0.4 0.4
  mass 1
}
WoodenBox {
  translation 2.27068 0.199608 -9.25878
  rotation -0.7427202375567159 0.05552739904947863 0.6672955542175413 4.03960723911127e-16
  name "wooden box(23)"
  size 0.4 0.4 0.4
  mass 1
}
WoodenBox {
  translation 2.25336 0.199608 -9.75119
  rotation -0.7427202375567159 0.05552739904947863 0.6672955542175413 4.03960723911127e-16
  name "wooden box(22)"
  size 0.4 0.4 0.4
  mass 1
}
WoodenBox {
  translation -1.74681 0.199608 -9.26089
  rotation -0.7427202375567159 0.05552739904947863 0.6672955542175413 4.03960723911127e-16
  name "wooden box(21)"
  size 0.4 0.4 0.4
  mass 1
}
WoodenBox {
  translation -1.77014 0.199608 -8.74503
  rotation -0.7427202375567159 0.05552739904947863 0.6672955542175413 4.03960723911127e-16
  name "wooden box(20)"
  size 0.4 0.4 0.4
  mass 1
}
WoodenBox {
  translation -1.74643 0.199608 -8.26851
  rotation -0.7427202375567159 0.05552739904947863 0.6672955542175413 4.03960723911127e-16
  name "wooden box(19)"
  size 0.4 0.4 0.4
  mass 1
}
WoodenBox {
  translation -1.72205 0.199608 -7.24277
  rotation -0.7427202375567159 0.05552739904947863 0.6672955542175413 4.03960723911127e-16
  name "wooden box(18)"
  size 0.4 0.4 0.4
  mass 1
}
WoodenBox {
  translation -1.73173 0.199608 -6.25538
  rotation -0.7427202375567159 0.05552739904947863 0.6672955542175413 4.03960723911127e-16
  name "wooden box(17)"
  size 0.4 0.4 0.4
  mass 1
}
WoodenBox {
  translation 3.47051 0.199608 -9.27412
  rotation -0.7427202375567159 0.05552739904947863 0.6672955542175413 4.03960723911127e-16
  name "wooden box(16)"
  size 0.4 0.4 0.4
  mass 1
}
WoodenBox {
  translation -5.75425 0.199608 -6.27946
  rotation -0.7427202375567159 0.05552739904947863 0.6672955542175413 4.03960723911127e-16
  name "wooden box(10)"
  size 0.4 0.4 0.4
  mass 1
}
WoodenBox {
  translation -5.76118 0.199608 -8.76107
  rotation -0.7427202375567159 0.05552739904947863 0.6672955542175413 4.03960723911127e-16
  name "wooden box(8)"
  size 0.4 0.4 0.4
  mass 1
}
WoodenBox {
  translation -5.74556 0.199608 -9.7345
  rotation -0.7427202375567159 0.05552739904947863 0.6672955542175413 4.03960723911127e-16
  name "wooden box(7)"
  size 0.4 0.4 0.4
  mass 1
}
WoodenBox {
  translation -5.70118 0.199608 -8.2661
  rotation -0.7427202375567159 0.05552739904947863 0.6672955542175413 4.03960723911127e-16
  name "wooden box(3)"
  size 0.4 0.4 0.4
  mass 1
}
WoodenBox {
  translation -9.262529999999947 0.19960760039112174 -9.716739999999946
  rotation 0.6797844015455953 0.001243312761206183 -0.7334109500059804 -4.3503820555425317e-16
  name "wooden box(2)"
  size 0.4 0.4 0.4
  mass 1
}
WoodenBox {
  translation -8.720000000031984 0.24960759926646575 -9.25
  rotation -5.253811138040533e-05 0.0865393598610116 -0.9962484310826257 1.7653723808943164e-13
  name "wooden box(1)"
  size 0.5 0.5 0.5
  mass 1
}
DEF MY_ROBOT Robot {
  translation -9.749999999999993 0.039720979328951106 -9.249999999451703
  rotation 6.853225770908804e-09 1 6.853201265506968e-09 1.570800000000072
  children [
    DEF BODY Shape {
      appearance PBRAppearance {
        baseColor 0.917647 0.145098 0.145098
        roughness 1
        metalness 0
      }
      geometry Box {
        size 0.1 0.05 0.2
      }
    }
    Transform {
      translation 0 0 0.11
      children [
        Shape {
          appearance PBRAppearance {
          }
          geometry Box {
            size 0.015 0.015 0.03
          }
        }
      ]
    }
    DEF wheelLeftF HingeJoint {
      jointParameters HingeJointParameters {
        position 10.843115051545151
        anchor 0.06 0 0.05
      }
      device [
        PositionSensor {
          name "ps_left"
        }
        RotationalMotor {
          name "leftF"
        }
      ]
      endPoint Solid {
        translation 0.06 0 0.05
        rotation -0.6045280952661543 0.6045303158253317 0.5187377750675195 2.184545228899538
        children [
          DEF WHEEL Shape {
            appearance PBRAppearance {
              baseColor 0.305882 0.898039 0.25098
              roughness 1
              metalness 0
            }
            geometry Cylinder {
              height 0.02
              radius 0.04
              subdivision 24
            }
          }
        ]
        boundingObject USE WHEEL
        physics Physics {
        }
      }
    }
    DEF wheelRightF HingeJoint {
      jointParameters HingeJointParameters {
        position -10.843119380645733
        anchor -0.06 0 0.05
      }
      device [
        PositionSensor {
          name "ps_right"
        }
        RotationalMotor {
          name "rightF"
        }
      ]
      endPoint Solid {
        translation -0.06 0 0.05
        rotation 0.6045273827775669 -0.6045296033341284 0.518739435713911 2.184542611838151
        children [
          USE WHEEL
        ]
        name "solid(1)"
        boundingObject USE WHEEL
        physics Physics {
        }
      }
    }
    DEF wheelLeftR HingeJoint {
      jointParameters HingeJointParameters {
        position 10.843119380818516
        anchor 0.06 0 -0.05
      }
      device [
        RotationalMotor {
          name "leftR"
        }
      ]
      endPoint Solid {
        translation 0.06 0 -0.05
        rotation -0.6045273827494028 0.6045296033059631 0.5187394357795558 2.1845426117346984
        children [
          USE WHEEL
        ]
        name "solid(2)"
        boundingObject USE WHEEL
        physics Physics {
        }
      }
    }
    DEF wheelRightR HingeJoint {
      jointParameters HingeJointParameters {
        position -10.843115051307661
        anchor -0.06 0 -0.05
      }
      device [
        RotationalMotor {
          name "rightR"
        }
      ]
      endPoint Solid {
        translation -0.06 0 -0.05
        rotation 0.6045280953052407 -0.6045303158644176 0.5187377749764186 2.184545229043107
        children [
          USE WHEEL
        ]
        name "solid(3)"
        boundingObject USE WHEEL
        physics Physics {
        }
      }
    }
    Compass {
    }
    InertialUnit {
      name "iu"
    }
    DistanceSensor {
      translation 0 -0.0075 0.122
      rotation 0 0 1 -1.5707
      name "ds_fall1"
    }
    DistanceSensor {
      translation 0 0.0075 0.122
      rotation 0 0 1 1.5707
      name "ds_fall2"
    }
    DEF front_ds_gp Transform {
      translation 0 -0.008 0
      rotation 1 0 0 -0.06
      children [
        DistanceSensor {
          translation -9.63268e-07 0 0.125
          rotation 0 1 0 -1.5708
          name "ds_front"
          lookupTable [
            0 0 0
            0.8 2000 0
          ]
        }
        DistanceSensor {
          translation 0 0 0.125
          rotation 0 1 0 -1.83
          name "ds_front_right"
          lookupTable [
            0 0 0
            0.8 2000 0
          ]
        }
        DistanceSensor {
          translation 0 0 0.125
          rotation 0 1 0 -1.3116
          name "ds_front_left"
          lookupTable [
            0 0 0
            0.8 2000 0
          ]
        }
      ]
    }
    DistanceSensor {
      translation 0.05 0 0
      name "ds_left"
      lookupTable [
        0 0 0
        0.8 2000 0
      ]
    }
    DistanceSensor {
      translation -0.05 0 0
      rotation 0 1 0 3.1414
      name "ds_right"
      lookupTable [
        0 0 0
        0.8 2000 0
      ]
    }
  ]
  boundingObject USE BODY
  physics Physics {
    density -1
    mass 1
  }
  controller "path_finding_next_grid"
  supervisor TRUE
}
